Workbook

Sheet Overall Summary
A1: WHOLECART — OVERALL TEST EXECUTION SUMMARY
A2: Live summary based on the Status values in the Functional Test Cases sheet.
A4: Overall Execution Status
A5: Metric | B5: Count | C5: Percentage
A6: Total Test Cases | B6: =COUNTA('Functional Test Cases'!A2:A1000) -> 76 | C6: =IFERROR(B6/$B$6,0) -> 1
A7: Passed | B7: =COUNTIF('Functional Test Cases'!M2:M1000,"PASS") -> 45 | C7: =IFERROR(B7/$B$6,0) -> 0.59210526
A8: Failed | B8: =COUNTIF('Functional Test Cases'!M2:M1000,"FAIL") -> 27 | C8: =IFERROR(B8/$B$6,0) -> 0.35526316
A9: Not Run | B9: =COUNTIF('Functional Test Cases'!M2:M1000,"Not Run")+COUNTIF('Functional Test Cases'!M2:M1000,"NOT RUN") -> 8 | C9: =IFERROR(B9/$B$6,0) -> 0.10526316
A10: Blocked | B10: =COUNTIF('Functional Test Cases'!M2:M1000,"Blocked")+COUNTIF('Functional Test Cases'!M2:M1000,"BLOCKED") -> 0 | C10: =IFERROR(B10/$B$6,0) -> 0
A11: Other / Blank Status | B11: =MAX(0,B6-SUM(B7:B10)) -> 0 | C11: =IFERROR(B11/$B$6,0) -> 0
A12: Executed (Pass + Fail) | B12: =B7+B8 -> 72 | C12: =IFERROR(B12/$B$6,0) -> 0.94736842
A13: Pass Rate of Executed | B13: =IFERROR(B7/B12,0) -> 0.625 | C13: =IFERROR(B7/B12,0) -> 0.625
A16: Module-wise Test Case Summary | H16: Priority-wise Summary
A17: Module | B17: Total | C17: Pass | D17: Fail | E17: Not Run | F17: Pass Rate (Executed) | H17: Priority | I17: Total | J17: Pass | K17: Fail
A18: Authentication | B18: =COUNTIF('Functional Test Cases'!$B$2:$B$1000,A18) -> 5 | C18: =COUNTIFS('Functional Test Cases'!$B$2:$B$1000,A18,'Functional Test Cases'!$M$2:$M$1000,"PASS") -> 3 | D18: =COUNTIFS('Functional Test Cases'!$B$2:$B$1000,A18,'Functional Test Cases'!$M$2:$M$1000,"FAIL") -> 2 | E18: =COUNTIFS('Functional Test Cases'!$B$2:$B$1000,A18,'Functional Test Cases'!$M$2:$M$1000,"Not Run")+COUNTIFS('Functional Test Cases'!$B$2:$B$1000,A18,'Functional Test Cases'!$M$2:$M$1000,"NOT RUN") -> 0 | F18: =IFERROR(C18/(C18+D18),0) -> 0.6 | H18: Critical | I18: =COUNTIF('Functional Test Cases'!$N$2:$N$1000,H18) -> 16 | J18: =COUNTIFS('Functional Test Cases'!$N$2:$N$1000,H18,'Functional Test Cases'!$M$2:$M$1000,"PASS") -> 8 | K18: =COUNTIFS('Functional Test Cases'!$N$2:$N$1000,H18,'Functional Test Cases'!$M$2:$M$1000,"FAIL") -> 8
A19: Cancellation | B19: =COUNTIF('Functional Test Cases'!$B$2:$B$1000,A19) -> 4 | C19: =COUNTIFS('Functional Test Cases'!$B$2:$B$1000,A19,'Functional Test Cases'!$M$2:$M$1000,"PASS") -> 2 | D19: =COUNTIFS('Functional Test Cases'!$B$2:$B$1000,A19,'Functional Test Cases'!$M$2:$M$1000,"FAIL") -> 2 | E19: =COUNTIFS('Functional Test Cases'!$B$2:$B$1000,A19,'Functional Test Cases'!$M$2:$M$1000,"Not Run")+COUNTIFS('Functional Test Cases'!$B$2:$B$1000,A19,'Functional Test Cases'!$M$2:$M$1000,"NOT RUN") -> 0 | F19: =IFERROR(C19/(C19+D19),0) -> 0.5 | H19: High | I19: =COUNTIF('Functional Test Cases'!$N$2:$N$1000,H19) -> 52 | J19: =COUNTIFS('Functional Test Cases'!$N$2:$N$1000,H19,'Functional Test Cases'!$M$2:$M$1000,"PASS") -> 35 | K19: =COUNTIFS('Functional Test Cases'!$N$2:$N$1000,H19,'Functional Test Cases'!$M$2:$M$1000,"FAIL") -> 13
A20: Cart | B20: =COUNTIF('Functional Test Cases'!$B$2:$B$1000,A20) -> 10 | C20: =COUNTIFS('Functional Test Cases'!$B$2:$B$1000,A20,'Functional Test Cases'!$M$2:$M$1000,"PASS") -> 6 | D20: =COUNTIFS('Functional Test Cases'!$B$2:$B$1000,A20,'Functional Test Cases'!$M$2:$M$1000,"FAIL") -> 4 | E20: =COUNTIFS('Functional Test Cases'!$B$2:$B$1000,A20,'Functional Test Cases'!$M$2:$M$1000,"Not Run")+COUNTIFS('Functional Test Cases'!$B$2:$B$1000,A20,'Functional Test Cases'!$M$2:$M$1000,"NOT RUN") -> 0 | F20: =IFERROR(C20/(C20+D20),0) -> 0.6 | H20: Low | I20: =COUNTIF('Functional Test Cases'!$N$2:$N$1000,H20) -> 1 | J20: =COUNTIFS('Functional Test Cases'!$N$2:$N$1000,H20,'Functional Test Cases'!$M$2:$M$1000,"PASS") -> 0 | K20: =COUNTIFS('Functional Test Cases'!$N$2:$N$1000,H20,'Functional Test Cases'!$M$2:$M$1000,"FAIL") -> 1
A21: Catalogue/Search | B21: =COUNTIF('Functional Test Cases'!$B$2:$B$1000,A21) -> 9 | C21: =COUNTIFS('Functional Test Cases'!$B$2:$B$1000,A21,'Functional Test Cases'!$M$2:$M$1000,"PASS") -> 5 | D21: =COUNTIFS('Functional Test Cases'!$B$2:$B$1000,A21,'Functional Test Cases'!$M$2:$M$1000,"FAIL") -> 4 | E21: =COUNTIFS('Functional Test Cases'!$B$2:$B$1000,A21,'Functional Test Cases'!$M$2:$M$1000,"Not Run")+COUNTIFS('Functional Test Cases'!$B$2:$B$1000,A21,'Functional Test Cases'!$M$2:$M$1000,"NOT RUN") -> 0 | F21: =IFERROR(C21/(C21+D21),0) -> 0.55555556 | H21: Medium | I21: =COUNTIF('Functional Test Cases'!$N$2:$N$1000,H21) -> 7 | J21: =COUNTIFS('Functional Test Cases'!$N$2:$N$1000,H21,'Functional Test Cases'!$M$2:$M$1000,"PASS") -> 2 | K21: =COUNTIFS('Functional Test Cases'!$N$2:$N$1000,H21,'Functional Test Cases'!$M$2:$M$1000,"FAIL") -> 5
A22: Checkout | B22: =COUNTIF('Functional Test Cases'!$B$2:$B$1000,A22) -> 19 | C22: =COUNTIFS('Functional Test Cases'!$B$2:$B$1000,A22,'Functional Test Cases'!$M$2:$M$1000,"PASS") -> 13 | D22: =COUNTIFS('Functional Test Cases'!$B$2:$B$1000,A22,'Functional Test Cases'!$M$2:$M$1000,"FAIL") -> 6 | E22: =COUNTIFS('Functional Test Cases'!$B$2:$B$1000,A22,'Functional Test Cases'!$M$2:$M$1000,"Not Run")+COUNTIFS('Functional Test Cases'!$B$2:$B$1000,A22,'Functional Test Cases'!$M$2:$M$1000,"NOT RUN") -> 0 | F22: =IFERROR(C22/(C22+D22),0) -> 0.68421053
A23: Delivery Slot Change | B23: =COUNTIF('Functional Test Cases'!$B$2:$B$1000,A23) -> 3 | C23: =COUNTIFS('Functional Test Cases'!$B$2:$B$1000,A23,'Functional Test Cases'!$M$2:$M$1000,"PASS") -> 2 | D23: =COUNTIFS('Functional Test Cases'!$B$2:$B$1000,A23,'Functional Test Cases'!$M$2:$M$1000,"FAIL") -> 1 | E23: =COUNTIFS('Functional Test Cases'!$B$2:$B$1000,A23,'Functional Test Cases'!$M$2:$M$1000,"Not Run")+COUNTIFS('Functional Test Cases'!$B$2:$B$1000,A23,'Functional Test Cases'!$M$2:$M$1000,"NOT RUN") -> 0 | F23: =IFERROR(C23/(C23+D23),0) -> 0.66666667
A24: Exchanges | B24: =COUNTIF('Functional Test Cases'!$B$2:$B$1000,A24) -> 3 | C24: =COUNTIFS('Functional Test Cases'!$B$2:$B$1000,A24,'Functional Test Cases'!$M$2:$M$1000,"PASS") -> 1 | D24: =COUNTIFS('Functional Test Cases'!$B$2:$B$1000,A24,'Functional Test Cases'!$M$2:$M$1000,"FAIL") -> 2 | E24: =COUNTIFS('Functional Test Cases'!$B$2:$B$1000,A24,'Functional Test Cases'!$M$2:$M$1000,"Not Run")+COUNTIFS('Functional Test Cases'!$B$2:$B$1000,A24,'Functional Test Cases'!$M$2:$M$1000,"NOT RUN") -> 0 | F24: =IFERROR(C24/(C24+D24),0) -> 0.33333333 | H24: Bug Status Summary
A25: Invoice | B25: =COUNTIF('Functional Test Cases'!$B$2:$B$1000,A25) -> 5 | C25: =COUNTIFS('Functional Test Cases'!$B$2:$B$1000,A25,'Functional Test Cases'!$M$2:$M$1000,"PASS") -> 3 | D25: =COUNTIFS('Functional Test Cases'!$B$2:$B$1000,A25,'Functional Test Cases'!$M$2:$M$1000,"FAIL") -> 1 | E25: =COUNTIFS('Functional Test Cases'!$B$2:$B$1000,A25,'Functional Test Cases'!$M$2:$M$1000,"Not Run")+COUNTIFS('Functional Test Cases'!$B$2:$B$1000,A25,'Functional Test Cases'!$M$2:$M$1000,"NOT RUN") -> 2 | F25: =IFERROR(C25/(C25+D25),0) -> 0.75 | H25: Bug Status | I25: Count
A26: Order History | B26: =COUNTIF('Functional Test Cases'!$B$2:$B$1000,A26) -> 2 | C26: =COUNTIFS('Functional Test Cases'!$B$2:$B$1000,A26,'Functional Test Cases'!$M$2:$M$1000,"PASS") -> 2 | D26: =COUNTIFS('Functional Test Cases'!$B$2:$B$1000,A26,'Functional Test Cases'!$M$2:$M$1000,"FAIL") -> 0 | E26: =COUNTIFS('Functional Test Cases'!$B$2:$B$1000,A26,'Functional Test Cases'!$M$2:$M$1000,"Not Run")+COUNTIFS('Functional Test Cases'!$B$2:$B$1000,A26,'Functional Test Cases'!$M$2:$M$1000,"NOT RUN") -> 0 | F26: =IFERROR(C26/(C26+D26),0) -> 1 | H26: Open | I26: =COUNTIF(Bugs!$N$2:$N$1000,H26) -> 20
A27: Order Lifecycle | B27: =COUNTIF('Functional Test Cases'!$B$2:$B$1000,A27) -> 4 | C27: =COUNTIFS('Functional Test Cases'!$B$2:$B$1000,A27,'Functional Test Cases'!$M$2:$M$1000,"PASS") -> 4 | D27: =COUNTIFS('Functional Test Cases'!$B$2:$B$1000,A27,'Functional Test Cases'!$M$2:$M$1000,"FAIL") -> 0 | E27: =COUNTIFS('Functional Test Cases'!$B$2:$B$1000,A27,'Functional Test Cases'!$M$2:$M$1000,"Not Run")+COUNTIFS('Functional Test Cases'!$B$2:$B$1000,A27,'Functional Test Cases'!$M$2:$M$1000,"NOT RUN") -> 0 | F27: =IFERROR(C27/(C27+D27),0) -> 1
A28: Redelivery | B28: =COUNTIF('Functional Test Cases'!$B$2:$B$1000,A28) -> 2 | C28: =COUNTIFS('Functional Test Cases'!$B$2:$B$1000,A28,'Functional Test Cases'!$M$2:$M$1000,"PASS") -> 1 | D28: =COUNTIFS('Functional Test Cases'!$B$2:$B$1000,A28,'Functional Test Cases'!$M$2:$M$1000,"FAIL") -> 1 | E28: =COUNTIFS('Functional Test Cases'!$B$2:$B$1000,A28,'Functional Test Cases'!$M$2:$M$1000,"Not Run")+COUNTIFS('Functional Test Cases'!$B$2:$B$1000,A28,'Functional Test Cases'!$M$2:$M$1000,"NOT RUN") -> 0 | F28: =IFERROR(C28/(C28+D28),0) -> 0.5
A29: Refunds | B29: =COUNTIF('Functional Test Cases'!$B$2:$B$1000,A29) -> 5 | C29: =COUNTIFS('Functional Test Cases'!$B$2:$B$1000,A29,'Functional Test Cases'!$M$2:$M$1000,"PASS") -> 1 | D29: =COUNTIFS('Functional Test Cases'!$B$2:$B$1000,A29,'Functional Test Cases'!$M$2:$M$1000,"FAIL") -> 4 | E29: =COUNTIFS('Functional Test Cases'!$B$2:$B$1000,A29,'Functional Test Cases'!$M$2:$M$1000,"Not Run")+COUNTIFS('Functional Test Cases'!$B$2:$B$1000,A29,'Functional Test Cases'!$M$2:$M$1000,"NOT RUN") -> 0 | F29: =IFERROR(C29/(C29+D29),0) -> 0.2
A30: Reorder | B30: =COUNTIF('Functional Test Cases'!$B$2:$B$1000,A30) -> 2 | C30: =COUNTIFS('Functional Test Cases'!$B$2:$B$1000,A30,'Functional Test Cases'!$M$2:$M$1000,"PASS") -> 2 | D30: =COUNTIFS('Functional Test Cases'!$B$2:$B$1000,A30,'Functional Test Cases'!$M$2:$M$1000,"FAIL") -> 0 | E30: =COUNTIFS('Functional Test Cases'!$B$2:$B$1000,A30,'Functional Test Cases'!$M$2:$M$1000,"Not Run")+COUNTIFS('Functional Test Cases'!$B$2:$B$1000,A30,'Functional Test Cases'!$M$2:$M$1000,"NOT RUN") -> 0 | F30: =IFERROR(C30/(C30+D30),0) -> 1
A31: Statements | B31: =COUNTIF('Functional Test Cases'!$B$2:$B$1000,A31) -> 3 | C31: =COUNTIFS('Functional Test Cases'!$B$2:$B$1000,A31,'Functional Test Cases'!$M$2:$M$1000,"PASS") -> 0 | D31: =COUNTIFS('Functional Test Cases'!$B$2:$B$1000,A31,'Functional Test Cases'!$M$2:$M$1000,"FAIL") -> 0 | E31: =COUNTIFS('Functional Test Cases'!$B$2:$B$1000,A31,'Functional Test Cases'!$M$2:$M$1000,"Not Run")+COUNTIFS('Functional Test Cases'!$B$2:$B$1000,A31,'Functional Test Cases'!$M$2:$M$1000,"NOT RUN") -> 6 | F31: =IFERROR(C31/(C31+D31),0) -> 0

Sheet Functional Test Cases
A1: Test Case ID | B1: Module | C1: User Type | D1: Test Case Title | E1: Test Case Description | F1: Preconditions | G1: Test Steps | H1: Test Data | I1: Expected Result | J1: Actual Result | K1: Test Case Type | L1: Application Environment | M1: Status | N1: Priority | O1: Bug ID
A2: WC-TC-0001 | B2: Authentication | C2: Buyer/Seller/Operator | D2: Login with valid credentials | E2: Verify each role can authenticate using a valid account. | F2: Application is available; test accounts exist. | G2: 1. Open login page. 2. Enter valid username and password. 3. Click Log in. | H2: buyer1 / Test@123; seller1 / Test@123; operator / Test@123 | I2: Login succeeds and the user is directed to the appropriate role landing page. | J2: Logged in as expected | K2: Smoke | L2: QA / Test Environment | M2: PASS | N2: Critical
A3: WC-TC-0002 | B3: Authentication | C3: Buyer/Seller/Operator | D3: Login without credentials | E3: Verify the login is rejected when there is no value in the username/password | G3: 1. Open login page. 2. Click Log in. | I3: Login should be rejected, Toast message should be displayed as username/password should not be empty | J3: It is displaying the API response value in the browser that the username/password value is null | K3: Negative | L3: QA / Test Environment | M3: FAIL | N3: Critical | O3: Bug-02
A4: WC-TC-0003 | B4: Authentication | C4: Buyer/Seller/Operator | D4: Reject invalid password | E4: Verify login is rejected when password is incorrect. | F4: User account exists. | G4: 1. Open login page. 2. Enter valid username and incorrect password. 3. Submit. | H4: buyer1 / Wrong@123 | I4: Login is rejected; no authenticated session is created. | J4: Wrong username or password' message is displayed, no authentication session created | K4: Negative | L4: QA / Test Environment | M4: PASS | N4: High
A5: WC-TC-0004 | B5: Authentication | C5: Buyer/Seller/Operator | D5: Reject unknown username | E5: Verify an unknown account cannot log in. | F5: Application is available. | G5: 1. Open login page. 2. Enter unknown username and any password. 3. Submit. | H5: unknown_user / Test@123 | I5: Login is rejected with a safe error message. | J5: Wrong username or password' message is displayed, no authentication session created | K5: Negative | L5: QA / Test Environment | M5: PASS | N5: High
A6: WC-TC-0005 | B6: Authentication | C6: Buyer/Seller/Operator | D6: Role-based page access | E6: Verify a user cannot access another role's restricted pages. | F6: Buyer, seller and operator accounts exist. | G6: 1. Log in as buyer. 2. Navigate directly to seller order-management and operator settings URLs. 3. Repeat for seller and operator roles. | H6: buyer1; seller2; operator | I6: Restricted pages/actions are denied for unauthorized roles; no protected data is disclosed. | J6: Login page is getting displayed but the session was not getting logged out or no unauthorized message were displayed. | K6: Security | L6: QA / Test Environment | M6: FAIL | N6: Critical | O6: Bug-01
A7: WC-TC-0006 | B7: Catalogue/Search | C7: Buyer | D7: Catalogue displays in-stock products | E7: Verify catalogue excludes products with zero stock. | F7: Buyer is logged in; catalogue has in-stock and out-of-stock products. | G7: 1. Open catalogue. 2. Review listed products. 3. Search for a known out-of-stock SKU. | H7: In-stock SKU and zero-stock SKU | I7: Only products with available stock appear in catalogue and search results; zero-stock products are not returned. | J7: Zero-stock products are getting listed in the catelogues. | K7: Functional | L7: QA / Test Environment | M7: FAIL | N7: High | O7: Bug-03
A8: WC-TC-0007 | B8: Catalogue/Search | C8: Buyer | D8: Search by product name | E8: Verify search returns matching products by name. | F8: Buyer is logged in; matching product exists. | G8: 1. Enter a full or partial product name. 2. Click Search. | H8: Chef's Banana Chips | I8: Matching product(s) are shown with correct SKU, category and price. | J8: Given product name only should be listed in the catelogue page. | K8: Functional | L8: QA / Test Environment | M8: PASS | N8: Medium
A9: WC-TC-0008 | B9: Catalogue/Search | C9: Buyer | D9: Search by product name | E9: Verify the pagination on searching the product name | F9: Buyer is logged in; matching product exists. | G9: 1. Enter a full or partial product name. 2. Click Search. | H9: Chef's Banana Chips | I9: Matching product(s) are shown with correct SKU, category and price. | J9: Pagination was not displaying after searching the product | K9: Functional | L9: QA / Test Environment | M9: FAIL | N9: Medium | O9: Bug-05
A10: WC-TC-0009 | B10: Catalogue/Search | C10: Buyer | D10: Search by SKU | E10: Verify exact SKU search returns the correct product. | F10: Buyer is logged in; SKU exists. | G10: 1. Enter an existing SKU. 2. Click Search. | H10: SKU-0475 | I10: Correct product is returned. | J10: Given product name only should be listed in the catelogue page. | K10: Functional | L10: QA / Test Environment | M10: PASS | N10: Medium
A11: WC-TC-0010 | B11: Catalogue/Search | C11: Buyer | D11: Search with no matches | E11: Verify empty-result behavior. | F11: Buyer is logged in. | G11: 1. Search for a non-existent name/SKU. | H11: NO-SUCH-SKU-999 | I11: No products are returned; a clear empty-result message is displayed. | J11: No product found message was not displayed | K11: Functional | L11: QA / Test Environment | M11: FAIL | N11: Medium | O11: Bug-04
A12: WC-TC-0011 | B12: Catalogue/Search | C12: Buyer | D12: Filter catalogue by category | E12: Verify category filter limits results. | F12: Buyer is logged in; products exist in multiple categories. | G12: 1. Select Grains. 2. Click Search. 3. Inspect each result. | H12: Category=Grains | I12: All returned products belong to Grains; products from other categories are excluded. | J12: Based on the selected category the products are getting displayed | K12: Functional | L12: QA / Test Environment | M12: PASS | N12: High
A13: WC-TC-0012 | B13: Catalogue/Search | C13: Buyer | D13: Catalogue prices exclude tax | E13: Verify displayed piece and case prices are net prices. | F13: Buyer is logged in; product tax rate and price are known. | G13: 1. Open catalogue. 2. Compare displayed prices with product configuration. | H13: SKU-0475; piece price ₹62.75; case price ₹346.38; tax 18% | I13: Catalogue displays configured prices excluding tax; tax is shown separately where applicable. | J13: Catalogue displayed the expected given prices in the table | K13: Functional | L13: QA / Test Environment | M13: PASS | N13: High
A14: WC-TC-0013 | B14: Catalogue/Search | C14: Buyer | D14: Open product detail | E14: Verify product details show price, tax, stock and unit options. | F14: Buyer is logged in; product is in stock. | G14: 1. Open a catalogue product link. 2. Review details. | H14: SKU-0475 | I14: Product name, SKU, category, seller, piece/case prices, tax rate and available stock are correct. | J14: Expected fields and values are dispalyed for the given product | K14: Functional | L14: QA / Test Environment | M14: PASS | N14: High
A15: WC-TC-0014 | B15: Catalogue/Search | C15: Buyer | D15: Search the product and select the category | E15: Verify the product list on search the product and selecting the category | F15: Buyer is logged in; products exist in a category | G15: 1. Select Grains. 2. Click Search. 3. Enter the search text and search it. 4. Select the category and search. | H15: Search Text = Chef Category = Grains | I15: The product list should be loaded based on the given search text and the category | J15: The category filter was not getting applied on searching the text | K15: Functional | L15: QA / Test Environment | M15: FAIL | N15: Low | O15: Bug-06
A16: WC-TC-0015 | B16: Cart | C16: Buyer | D16: Add product by case | E16: Verify a buyer can add a valid case quantity from product detail. | F16: Buyer is logged in; product has enough stock. | G16: 1. Open product detail. 2. Select Case. 3. Enter quantity 1. 4. Click Add to cart. | H16: SKU-0475; case size 6; quantity 1 | I16: Cart contains the product as a case; line total equals case price × quantity; success feedback is shown. | J16: Case is getting added in the cart with the given quantity | K16: Smoke | L16: QA / Test Environment | M16: PASS | N16: Critical
A17: WC-TC-0016 | B17: Cart | C17: Buyer | D17: Add product by piece | E17: Verify a buyer can add a product in piece units. | F17: Buyer is logged in; product has enough stock. | G17: 1. Open product detail. 2. Select Piece. 3. Enter quantity 1. 4. Add to cart. | H17: SKU-0475; piece price ₹62.75; quantity 1 | I17: Cart contains a piece line at the piece price. | J17: Piece is getting added in the cart with the given value | K17: Functional | L17: QA / Test Environment | M17: PASS | N17: High
A18: WC-TC-0017 | B18: Cart | C18: Buyer | D18: Cart allows quantity minimum 1 | E18: Verify zero and negative quantities are rejected. | F18: Buyer has a product in cart. | G18: 1. Enter 0, then a negative quantity where input permits. 2. Update cart. | H18: 0; -1 | I18: Invalid quantities are rejected and cart totals remain unchanged. | J18: Expected message is getting dispalyed | K18: Negative | L18: QA / Test Environment | M18: PASS | N18: High
A19: WC-TC-0018 | B19: Cart | C19: Buyer | D19: Cart quantity maximum 99 | E19: Verify the maximum cart-line quantity is enforced. | F19: Buyer is logged in; sufficient stock exists. | G19: 1. Add a product. 2. Set quantity to 99 and update. 3. Attempt quantity 100. | H19: 99; 100 | I19: Quantity 99 is accepted if stock allows; quantity above 99 is rejected. | J19: Expected message is getting dispalyed but after the message displayed if we enter the valid value the product was not added in the cart. | K19: Functional | L19: QA / Test Environment | M19: FAIL | N19: Medium | O19: Bug-07
A20: WC-TC-0019 | B20: Cart | C20: Buyer | D20: Cart quantity is empty in product details | E20: Verify the cart quantity is empty in the product details | F20: Buyer is logged in; sufficient stock exists. | G20: 1. Add a product. 2. Set quantity to empty 3. Click the Add to Cart button | I20: Prompt message should be displayed as "Enter the Quantity Number" | J20: It is displaying the API response value in the browser that the quantity value is null | K20: Functional | L20: QA / Test Environment | M20: FAIL | N20: Medium | O20: Bug-08
A21: WC-TC-0020 | B21: Cart | C21: Buyer | D21: Cart quantity is empty in the cart page | E21: Verify the cart quantity is empty in the cart page | F21: Buyer has a product in cart. | G21: 1. Open cart. 2. Clear the quantity of the product 3. Click the update button | I21: Prompt message should be displayed as "Enter the Quantity Number" | J21: It is displaying the API response value in the browser that the quantity value is null | K21: Functional | L21: QA / Test Environment | M21: FAIL | N21: High | O21: Bug-08
A22: WC-TC-0021 | B22: Cart | C22: Buyer | D22: Update cart line quantity | E22: Verify line and net totals recalculate after quantity update. | F22: Buyer has a product in cart. | G22: 1. Change quantity. 2. Click Update. 3. Check line total and net total. | H22: SKU-0475 piece ₹62.75; quantity 10 | I22: Line total equals ₹627.50; net total equals sum of all cart lines before tax. | J22: Based on the updated quantity value the total value is getting updated correctly | K22: Functional | L22: QA / Test Environment | M22: PASS | N22: High
A23: WC-TC-0022 | B23: Cart | C23: Buyer | D23: Stock prevents over-ordering | E23: Verify a cart cannot reserve more pieces than available stock. | F23: Known product stock is lower than requested quantity. | G23: 1. Attempt to add a case/piece quantity exceeding stock. 2. Proceed to update cart. | H23: Stock 5 pieces; request 6 pieces | I23: System blocks the excess quantity and explains stock availability; stock never becomes negative. | J23: No Prompt messages were displayed on execeeding the quantity value which is unavailable | K23: Negative | L23: QA / Test Environment | M23: FAIL | N23: High | O23: Bug-09
A24: WC-TC-0023 | B24: Cart | C24: Buyer | D24: Empty cart hides checkout button | E24: Verify checkout cannot be initiated from an empty cart. | F24: Buyer is logged in; cart is empty. | G24: 1. Open cart. 2. Inspect Proceed to checkout. | H24: Empty cart | I24: Proceed to checkout is hidden when cart is empty. | J24: Your cart is empty message is getting displayed | K24: Functional | L24: QA / Test Environment | M24: PASS | N24: High
A25: WC-TC-0024 | B25: Cart | C25: Buyer | D25: Same product in different units | E25: Verify piece and case lines are represented and totalled correctly. | F25: Buyer is logged in; product has sufficient stock. | G25: 1. Add product as case. 2. Add same product as piece. 3. Open cart. | H25: SKU-0475; 12 cases at ₹346.38 and 10 pieces at ₹62.75 | I25: Separate unit lines are shown; line totals and net total are correct. | J25: Separate unit lines are shown; line totals and net total are correct. | K25: Functional | L25: QA / Test Environment | M25: PASS | N25: High
A26: WC-TC-0025 | B26: Checkout | C26: Buyer | D26: Minimum order per seller at threshold | E26: Verify the minimum net order is enforced at exactly ₹2,000 per seller per approved CR-07. | F26: Buyer has cart items from one seller; settings reflect release notes. | G26: 1. Add products totalling exactly ₹2,000 net for one seller. 2. Proceed to checkout. | H26: Seller net = ₹2,000.00 | I26: Checkout accepts that seller's sub-order because the approved release-note minimum is ₹2,000 net. | J26: Order is getting placed | K26: Boundary | L26: QA / Test Environment | M26: PASS | N26: Critical
A27: WC-TC-0026 | B27: Checkout | C27: Buyer | D27: Minimum order below threshold | E27: Verify checkout rejects seller sub-order net below ₹2,000. | F27: Buyer has cart items from one seller. | G27: 1. Add items totalling ₹1,999.99 net for a seller. 2. Proceed to checkout. | H27: Seller net = ₹1,999.99 | I27: Checkout blocks submission and identifies the seller whose net amount is below ₹2,000. | J27: Expected message is getting displayed if the order is lesser than 2000 also the order was not placed | K27: Negative | L27: QA / Test Environment | M27: PASS | N27: Critical
A28: WC-TC-0027 | B28: Checkout | C28: Buyer | D28: Minimum evaluated separately per seller | E28: Verify each seller independently meets the minimum. | F28: Products from at least two sellers are available. | G28: 1. Add ₹2,500 from seller A and ₹1,800 from seller B. 2. Proceed to checkout. | H28: Seller A ₹2,500; seller B ₹1,800 | I28: Checkout rejects the seller B sub-order even though combined cart net exceeds the minimum. | J28: Order is getting placed eventhough the seller B value is lesser than 2000 | K28: Negative | L28: QA / Test Environment | M28: FAIL | N28: Critical | O28: Bug-10
A29: WC-TC-0028 | B29: Checkout | C29: Buyer | D29: Seller summary and grand total | E29: Verify checkout shows net, tax, delivery including tax and totals per seller. | F29: Cart contains eligible items; tax rates and seller grouping are known. | G29: 1. Proceed to checkout. 2. Inspect seller summary and grand total. | H29: Products taxed at 5% and 18%; seller nets around delivery threshold | I29: Each seller row shows correct net, tax, delivery fee including tax and total; grand total equals sum of seller totals. | J29: Net, Tax and delivery fee including tax and total and grant total are displaying as expected | K29: Functional | L29: QA / Test Environment | M29: PASS | N29: High
A30: WC-TC-0029 | B30: Checkout | C30: Buyer | D30: Tax aggregation and half-up rounding | E30: Verify tax is summed by rate and rounded half-up once per rate. | F30: Cart has multiple lines sharing a tax rate. | G30: 1. Add multiple products taxed at the same rate. 2. Open checkout. 3. Independently calculate rate-group totals. | H30: Several 5% lines and several 18% lines with fractional-paisa results | I30: Tax is calculated on the summed net value per tax rate and rounded half-up to the paisa once per rate. | J30: Tax were calculated based on the individual product tax percentage. Working fine as expected | K30: Calculation | L30: QA / Test Environment | M30: PASS | N30: Critical
A31: WC-TC-0030 | B31: Checkout | C31: Buyer | D31: Mixed tax rates | E31: Verify 5% and 18% taxes are independently calculated. | F31: Cart contains products at both tax rates. | G31: 1. Add products taxed at 5% and 18%. 2. Review checkout summary. | H31: Tax rates 5%, 18% | I31: Tax is grouped and rounded separately for each rate; total tax is the sum of the rounded rate groups. | J31: Tax were calculated based on the individual product tax percentage. Working fine as expected | K31: Functional | L31: QA / Test Environment | M31: PASS | N31: High
A32: WC-TC-0031 | B32: Checkout | C32: Buyer | D32: Delivery fee below ₹3,000 | E32: Verify a ₹100 fee plus 18% tax applies per seller sub-order below ₹3,000 net. | F32: A seller's net is below ₹3,000 and at least ₹2,000. | G32: 1. Add eligible products from that seller. 2. Proceed to checkout. | H32: Seller net ₹2,500 | I32: Delivery fee is ₹100 before tax plus ₹18 tax; checkout shows ₹118 delivery inclusive of tax. | J32: Delivery charges is getting displayed as 118 as expected when the total is less than 3000 | K32: Functional | L32: QA / Test Environment | M32: PASS | N32: High
A33: WC-TC-0032 | B33: Checkout | C33: Buyer | D33: No delivery fee at ₹3,000 threshold | E33: Verify delivery fee rule at exactly ₹3,000 net. | F33: Seller net can be set to exactly ₹3,000. | G33: 1. Add items totalling ₹3,000 net for one seller. 2. Proceed to checkout. | H33: Seller net ₹3,000.00 | I33: No delivery fee is charged for that seller because the rule applies only when net is below ₹3,000. | J33: Delivery charge is zero for this scenario | K33: Boundary | L33: QA / Test Environment | M33: PASS | N33: High
A34: WC-TC-0033 | B34: Checkout | C34: Buyer | D34: Delivery fee independently per seller | E34: Verify fee is assessed separately for each seller sub-order. | F34: Cart includes products from multiple sellers. | G34: 1. Add eligible items from two sellers, each below ₹3,000. 2. Review checkout. | H34: Seller A ₹2,200; seller B ₹2,700 | I34: Each qualifying seller sub-order has its own ₹100 fee plus ₹18 tax. | J34: For both the seller the delivery charges are displaying as 118 as expected. | K34: Functional | L34: QA / Test Environment | M34: PASS | N34: High
A35: WC-TC-0034 | B35: Checkout | C35: Buyer | D35: Delivery date range | E35: Verify date picker permits today through today + 7 days. | F35: Buyer is at checkout; store clock/time is known. | G35: 1. Open date picker. 2. Try today, today + 7 days, yesterday and today + 8 days. | H35: Date boundaries based on store clock | I35: Today and the next 7 days are selectable; dates outside the range are unavailable. | J35: We are able to select the date after 7 days | K35: Boundary | L35: QA / Test Environment | M35: FAIL | N35: Medium | O35: Bug-11
A36: WC-TC-0035 | B36: Checkout | C36: Buyer | D36: Delivery slot capacity | E36: Verify slots at capacity are disabled. | F36: A delivery slot has reached configured capacity of 5 orders. | G36: 1. Open checkout for that date. 2. Inspect slot availability. | H36: Orders per slot = 5; one slot already has 5 orders | I36: Full slot is disabled with a reason; a slot with capacity remains selectable. | J36: If the delivery slot exceed 5 that radio button got disabled | K36: Functional | L36: QA / Test Environment | M36: PASS | N36: High
A37: WC-TC-0036 | B37: Checkout | C37: Buyer | D37: Same-day morning slot unavailable | E37: Verify same-day 08:00–11:00 and 11:00–14:00 slots are unavailable. | F37: Store clock is set to today before cut-off. | G37: 1. Select today's delivery date. 2. Inspect all slots. | H37: Today; before 10:00 | I37: Morning slots are disabled with the same-day availability reason. | J37: Morning Slots are unavailable | K37: Functional | L37: QA / Test Environment | M37: PASS | N37: High
A38: WC-TC-0037 | B38: Checkout | C38: Buyer | D38: Same-day afternoon before cut-off | E38: Verify afternoon/evening slots can be booked before cut-off. | F38: Store clock is set to today before 10:00; slot has capacity. | G38: 1. Select today. 2. Select 14:00–17:00 or 17:00–20:00. 3. Place order. | H38: Store time 09:59:59; slot capacity available | I38: Same-day afternoon/evening slot is available and order submission succeeds if other rules pass. | J38: Afternoon Slots are available | K38: Boundary | L38: QA / Test Environment | M38: PASS | N38: High
A39: WC-TC-0038 | B39: Checkout | C39: Buyer | D39: Same-day order at exact cut-off | E39: Verify order is not treated as before cut-off at 07:10:00. | F39: Store clock can be fixed. | G39: 1. Set store clock to 07:10:00. 2. Select today. 3. Inspect afternoon/evening slots. | H39: Store time 07:10:00 | I39: Same-day slots requiring placement before cut-off are unavailable; exactly 07:10 does not qualify. or after 07:10 also the today slot should not displayed | J39: We are displaying the today afternoon slot | K39: Boundary | L39: QA / Test Environment | M39: FAIL | N39: Critical | O39: Bug-16
A40: WC-TC-0039 | B40: Checkout | C40: Buyer | D40: Next-day morning slots | E40: Verify morning slots can be booked for a future eligible date. | F40: Future date within 7-day range; slot has capacity. | G40: 1. Select tomorrow. 2. Inspect morning slots. | H40: Tomorrow; 08:00–11:00 and 11:00–14:00 | I40: Morning slots are available unless capacity is full. | J40: Slot is displaying if it is available for the other days. | K40: Functional | L40: QA / Test Environment | M40: PASS | N40: High
...

Sheet Bugs
A1: Defect ID | B1: Module | C1: Bug Description | D1: Preconditions | E1: Steps to Reproduce | F1: Test Data | G1: Expected Result | H1: Actual Result | I1: Severity | J1: Priority | K1: Evidence | L1: Linked Test Cases | M1: Environment | N1: Status | O1: Comment
A2: Bug-01 | B2: Authentication | C2: On accessing the other user URL, it is navigate to the login page | D2: Logged in as buyer1 | E2: 1. Logged in as buyer1 2. Launch the seller orders URL | F2: URL: http://13.200.185.1/c/ibrahim-5d1ff8/seller/orders | G2: The seller page should be restricted and display some message as restricted URL. | H2: Login page is getting displayed but still in the menu logout button is dispalying which means that the buyer session is still available | I2: High | J2: Medium | K2: Screenshot/Bug-01 | L2: WC-TC-0005 | M2: QA | N2: Open
A3: Bug-02 | B3: Authentication | C3: On Login the user without entering the username/password | E3: 1. Launch the Login page. 2. Click the Login button or press enter key without entering the text in the username/password | G3: It should display the warning message that the fields are empty | H3: It is displaying the API response in the browser that the field value is missing. This should be handled. | I3: Medium | J3: Medium | K3: Screenshot/Bug-02 | L3: WC-TC-0002 | M3: QA | N3: Open | O3: This bug is applicable if both the fields are displayed as empty or either one of them is empty.
A4: Bug-03 | B4: Catalogue/Search | C4: Zero-stock products listed in the catelogue page. | D4: Logged in as buyer1 | E4: 1. Logged in as buyer1 2. Search the product which is zero-stock in the seller products list | F4: Premium Basmati Rice | G4: It should not display the product which has zero-stocks in th catelogue page. | H4: The Product with zero stock was dispalying in the catelogue page. | I4: Low | J4: High | K4: Screenshot/Bug-03 | L4: WC-TC-0006 WC-TC-0043 | M4: QA | N4: Open | O4: It is displaying wtih or without filtering the product. The stock was not getting updated when the order has been placed.
A5: Bug-04 | B5: Catalogue/Search | C5: Search the product which is not available | D5: Logged in as buyer1 | E5: 1. Logged in as buyer1 2. Search the product which is not available in the product list page | F5: test product name | G5: It should displaye the message that the 'No Product Found' | H5: No message were displayed if the product is not available. | I5: Low | J5: Low | K5: Screenshot/Bug-04 | L5: WC-TC-0010 | M5: QA | N5: Open
A6: Bug-05 | B6: Catalogue/Search | C6: Search the product and verify the pagination | D6: Logged in as buyer1 | E6: 1. Logged in as buyer1 2. Search the product with partial name | F6: chef | G6: The pagination should be dispalyed if the product count is more than 24 | H6: Pagination was not getting displayed for searched product | I6: Low | J6: Low | K6: recordings/Bug-05.mp4 | L6: WC-TC-0008 | M6: QA | N6: Open
A7: Bug-06 | B7: Catalogue/Search | C7: Search the product and Select the category | D7: Logged in as buyer1 | E7: 1. Logged in as buyer1 2. Search the product with partial name 3. Select the Category and Search | F7: chef category = Grain | G7: The products should be listed based on the given text and the selected category | H7: Category selection filter was not working if any text has been given in the search field | I7: Low | J7: Low | K7: Screenshot/Bug-06 | L7: WC-TC-0014 | M7: QA | N7: Open
A8: Bug-07 | B8: Cart | C8: Product not getting added to the cart when the boundary reached message is displayd | D8: Logged in as buyer1 | E8: 1. Logged in as buyer1 2. Select a product 3. Enter the numer greater than 100 or lesser than 1 4. Click the Add to cart button. 5. "Quantity must be a whole number from 1 to 99" 6. Enter the number between 1 to 99 and click the Add to car button | F8: Chef's Basmati Rice | G8: The product should be added in the cart | H8: Since the message(Quantity must be a whole number from 1 to 99) is getting displayed the product was not getting added in the cart. | I8: Medium | J8: Medium | K8: recordings/Bug-07.mp4 | L8: WC-TC-0018 | M8: QA | N8: Open
A9: Bug-08 | B9: Cart | C9: Add the product to the cart when the quantity is empty | D9: Logged in as buyer1 | E9: 1. Add a product. 2. Set quantity to empty 3. Click the Add to Cart button | G9: Prompt message should be displayed as "Enter the Quantity Number" | H9: It is displaying the API response value in the browser that the quantity value is null | I9: Medium | J9: Medium | K9: screenshot/Bug-08 | L9: WC-TC-0019 WC-TC-0020 | M9: QA | N9: Open | O9: Same bug is happening in the cart page too.
A10: Bug-09 | B10: Cart | C10: Verify a cart cannot reserve more pieces than available stock. | D10: Known product stock is lower than requested quantity. | E10: 1. Attempt to add a case/piece quantity exceeding stock. 2. Proceed to update cart. | F10: Stock 5 pieces; request 6 pieces | G10: System blocks the excess quantity and explains stock availability; stock never becomes negative. | H10: No Prompt messages were displayed on execeeding the quantity value which is unavailable | I10: Medium | J10: High | K10: screenshot/Bug-09 | L10: WC-TC-0022 | M10: QA | N10: Open
A11: Bug-10 | B11: Checkout | C11: Verify each seller independently meets the minimum net value | D11: Products from at least two sellers are available. | E11: 1. Add ₹2,500 from seller A and ₹1,800 from seller B. 2. Proceed to checkout. | F11: Seller A ₹2,500; seller B ₹1,800 | G11: Checkout rejects the seller B sub-order even though combined cart net exceeds the minimum. | H11: Order is getting placed eventhough the seller B value is lesser than 2000 | I11: Medium | J11: High | K11: recordings/Bug-10.mp4 | L11: WC-TC-0027 | M11: QA | N11: Open
A12: Bug-11 | B12: Checkout | C12: Verify date picker permits today through today + 7 days. | D12: Buyer is at checkout; store clock/time is known. | E12: 1. Open date picker. 2. Try today, today + 7 days, yesterday and today + 8 days. | F12: Date boundaries based on store clock | G12: Today and the next 7 days are selectable; dates outside the range are unavailable. | H12: We are able to select the date after 7 days | I12: Medium | J12: Medium | K12: screenshot/Bug-11 | L12: WC-TC-0034 | M12: QA | N12: Open
A13: Bug-12 | B13: Checkout | C13: Verify successful submission redirects to order history and shows order numbers. | D13: Cart satisfies minimums, stock and slot rules. | E13: 1. Select a valid date and slot. 2. Click Place order. | F13: Valid cart and available slot | G13: Order history opens and message reads 'Your order has been placed. Order number: {numbers}' with generated order number(s). | H13: Only Order placed message is displayed not the one in the requirement. | I13: Low | J13: Low | K13: screenshot/Bug-12 | L13: WC-TC-0040 | M13: QA | N13: Open
A14: Bug-13 | B14: Checkout | C14: Verify double-click/retry does not create duplicate orders. | D14: Valid checkout ready to submit. | E14: 1. Submit checkout twice rapidly or replay same submission. 2. Inspect order history and stock. | F14: Same checkout submitted twice | G14: Only one order is created; stock is decremented once. | H14: Duplicate order is getting created | I14: High | J14: High | K14: screenshot/Bug-13 | L14: WC-TC-0041 | M14: QA | N14: Open
A15: Bug-14 | B15: Cancellation | C15: Verify seller cancellation updates buyer-visible status. | D15: Seller has a cancellable order. | E15: 1. Log in as seller. 2. Cancel order. 3. Refresh buyer order history. | F15: Order status Placed or Accepted | G15: Buyer sees Cancelled status immediately. | H15: Selller's cancelation was not reflected in the Buyer's order list | I15: High | J15: High | K15: screenshot/Bug-14 | L15: WC-TC-0049 | M15: QA | N15: Open
A16: Bug-15 | B16: Cancellation | C16: Verify shipped orders cannot be cancelled. | D16: Order status is Shipped. | E16: 1. Open order. 2. Attempt cancellation. | F16: Status Shipped | G16: Cancellation is not offered or is rejected; order status and stock are unchanged. | H16: Once the order is in shipped status we are able to cancel it. | I16: High | J16: High | K16: recordings/Bug-15.mp4 | L16: WC-TC-0048 | M16: QA | N16: Open
A17: Bug-16 | B17: Checkout | C17: Verify order is not treated as before cut-off at 07:10:00. | D17: Store clock can be fixed. | E17: 1. Set store clock to 07:10:00. 2. Select today. 3. Inspect afternoon/evening slots. | F17: Store time 07:10:00 | G17: Same-day slots requiring placement before cut-off are unavailable; exactly 07:10 does not qualify. or after 07:10 also the today slot should not displayed | H17: We are displaying the today afternoon slot but we should not display it. | I17: Medium | J17: Medium | K17: screenshot/Bug-16 | L17: WC-TC-0038 | M17: QA | N17: Open
A18: Bug-17 | B18: Redelivery | C18: Verify redelivery slot follows date, capacity and cut-off rules. | D18: Order has failed delivery; store clock is controllable. | E18: 1. Attempt same-day morning slot. 2. Attempt same-day afternoon slot after cut-off. 3. Try valid future slot. | F18: Same-day slots and future slot | G18: Invalid slots are unavailable/rejected; only slots complying with BR-05 and BR-06 can be selected. | H18: We are able to select the unavialable slots in the redelivery section, restriction implementation was not applied here | I18: Medium | J18: Medium | K18: screenshot/Bug-17 | L18: WC-TC-0054 | M18: QA | N18: Open
A19: Bug-18 | B19: Redelivery | C19: Verify slot change is booked after request to the redelivery | D19: Order status is redelivery_requested. | E19: 1. Open order. 2. Attempt to change delivery slot. | F19: Status redelivery_requested | G19: Requested delivery date and slot update successfully. | H19: Slot change not available message is displayed when the order status is under redelivery_request | I19: Medium | J19: Medium | K19: screenshot/Bug-18 | L19: WC-TC-0057 | M19: QA | N19: Open
A20: Bug-19 | B20: Refunds | C20: Verify full refund request covers all order lines. | D20: Order is Delivered. | E20: 1. Open delivered order. 2. Request full refund. 3. Submit. | F20: Delivered order with multiple lines | G20: Full refund request includes all lines and ordered quantities. | H20: The refund request was not received to the seller | I20: Medium | J20: Medium | K20: recordings/Bug-19.mp4 | L20: WC-TC-0062 WC-TC-0065 WC-TC-0064 WC-TC-0061, WC-TC-0065 | M20: QA | N20: Open
A21: Bug-20 | B21: Invoice | C21: Verify tax by rate and delivery fee line reconcile to order total. | D21: Delivered order includes products at applicable tax rates and possibly a delivery fee. | E21: 1. Open invoice. 2. Calculate tax per rate and delivery fee independently. 3. Compare total. | F21: 5% and 18% lines; seller net below ₹3,000 | G21: Tax follows BR-07; delivery fee appears as a separate line per BR-08; invoice total equals order total. | H21: Delivery fee was not displayed in the invoice | I21: Medium | J21: Medium | K21: screenshot/Bug-20 | L21: WC-TC-0072 | M21: QA | N21: Open

Sheet Suggessions
A1: S.No. | B1: Suggessions
A2: 1 | B2: In the Checkout page, it is better to have a remove button for the products added in the cart
A3: 2 | B3: In the Order Page, On cancelling the order it is better to displayed the confirmation popup
A4: 3 | B4: In the Checkout page, we can display slot on selecting the date itself, also we can show/hide the show slot button
A5: 4 | B5: Order Details page, After cancelling the order it is better to not display the cancel order button.
A6: 5

Sheet Observation
A1: S.No | B1: Requirment | C1: ACtual
A2: 1 | B2: In the cart page, Quantities should be in dropdown. | C2: But we keep the textbox same as like in the product details page.
